Workbook
Name _: #REF!
Name __________________Lx1: #REF!
Name __________________Ly1: #REF!
Name __________________Lz1: #REF!
Name __________________Lz2: #REF!
Name __________________Mf1: #REF!
Name __________________Mf2: #REF!
Name __________________Wf1: #REF!
Name __________________Wf2: #REF!
Name _________________Lx1: #REF!
Name _________________Ly1: #REF!
Name _________________Lz1: #REF!
Name _________________Lz2: #REF!
Name _________________Mf1: #REF!
Name _________________Mf2: #REF!
Name _________________Wf1: #REF!
Name _________________Wf2: #REF!
Name ________________Lx1: #REF!
Name ________________Ly1: #REF!
Name ________________Lz1: #REF!
Name ________________Lz2: #REF!
Name ________________Mf1: #REF!
Name ________________Mf2: #REF!
Name ________________Wf1: #REF!
Name ________________Wf2: #REF!
Name _______________Lx1: #REF!
Name _______________Ly1: #REF!
Name _______________Lz1: #REF!
Name _______________Lz2: #REF!
Name _______________Mf1: #REF!
Name _______________Mf2: #REF!
Name _______________Wf1: #REF!
Name _______________Wf2: #REF!
Name ______________Lx1: #REF!
Name ______________Ly1: #REF!
Name ______________Lz1: #REF!
Name ______________Lz2: #REF!
Name ______________Mf1: #REF!
Name ______________Mf2: #REF!
Name ______________Wf1: #REF!
Name ______________Wf2: #REF!
Name _____________Lx1: #REF!
Name _____________Ly1: #REF!
Name _____________Lz1: #REF!
Name _____________Lz2: #REF!
Name _____________Mf1: #REF!
Name _____________Mf2: #REF!
Name _____________Wf1: #REF!
Name _____________Wf2: #REF!
Name ____________HSH1: #REF!
Name ____________HSH2: #REF!
Name ____________Lx1: #REF!
Name ____________Ly1: #REF!
Name ____________Lz1: #REF!
Name ____________Lz2: #REF!
Name ____________Mf1: #REF!
Name ____________Mf2: #REF!
Name ____________NP1: #REF!
Name ____________NP2: #REF!
Name ____________NSH1: #REF!

Sheet QUOTATION
G3: 5341 Perimeter Parkway Ct. Montgomery AL 36116 Email : tkelectricoffice@gmail.com
A4: Q U O T A T I O N
A6: 1 | B6: SERVICE PROVIDER | P6: 8 | Q6: PO NUMBER / DATE OF QUOTATION
B7: TK ELECTRIC LLC | P7: TKM101027 | Y7: 46070
B8: 765 Us Highway 80, Eden, GA 31307
A9: 2 | B9: CONSIGNEE | P9: 9 | Q9: REMARKS
B10: HMGMA
B11: Bryan County Megasite, Ellabell, GA 31308
A12: 3 | B12: CONTACT
B13: Mr. Hyungjoon Jang
B14: Hyungjoon.Jang@hmgma.com
A15: 4 | B15: PROJECT NAME | H15: 5 | I15: SERVICE PERIOD
B16: 800_POD INSPECTION | I16: 2026
A18: 6 | B18: CARRIER | H18: 7 | I18: SERVICE LOCATION | P18: 10 | Q18: PROJECT MANAGER | Y18: 11 | Z18: SAFETY MANAGER
B19: TK ELECTRIC LLC | I19: Ellabell ,GA | Q19: Park, Junggu | Z19: CHRIS, HILGER
A21: 12 | B21: PROJECT NAME & DESCRIPTION | P21: 13 | Q21: QTY | U21: 14 | V21: UNIT | Y21: 15 | Z21: S. TOTAL
A22: ='B.O.Q'!C9 -> ■POD INSPECTION
A23: ='B.O.Q'!C10 -> □ POWER DISTRIBUTION PLAN | P23: 1 | U23: LOT | Y23: =P23 -> 1
A24: ='B.O.Q'!C11 -> □ GROUNDING PLAN | P24: 1 | U24: LOT | Y24: =P24 -> 1
A25: ='B.O.Q'!C12 -> □ MECHANICAL POWER PLAN | P25: 1 | U25: LOT | Y25: =P25 -> 1
A26: ='B.O.Q'!C13 -> □ LIGHTING PLAN | P26: 1 | U26: LOT | Y26: =P26 -> 1
A27: CONDITIONS AND TERMS | P27: MATERIALS | Y27: ='B.O.Q'!M9 -> 244974.04
P28: LABOR | Y28: ='B.O.Q'!N9 -> 185226.87
P29: EXPENSE | Y29: ='B.O.Q'!O9 -> 30711.3
P30: EQUIPMENT | Y30: ='B.O.Q'!L15 -> 9300
P31: SUB. TOTAL | Y31: =SUM(Y27:AC30) -> 470212.21
P33: SAFETY / MANAGEMENT | Y33: ='B.O.Q'!L18 -> 18851.309
Y34: =SUM(Y31:AC33) -> 489063.52
A35: APPROVED BY : | P35: G. TOTAL | Y35: 489000
A38: DATE : | E38: =Y7 -> 46070 | W38: TAE K. KIM / PRESIDENT

Sheet B.O.Q
C1: [ B.O.Q ]
C2: PROJECT :POD INSPECTION
C3: CONSTRUCTION PERIOD : '2026
C4: SUBCONTRACTOR : TK ELECTRIC LLC
C5: 품 명 DESCRIPTION OF WORK | E5: 규 격 SPECIFICATION | F5: 단 위 UNIT | G5: Bill of Quantity | P5: 비 고 REMARKS
G6: 수 량 Q'ty | H6: ITEM PRICE PER ITEM | K6: 단 가 Unit Price | L6: 금 액 Amount | M6: ITEM PRICE PER CLASSIFICATION
H7: MATERIAL | I7: LABOR | J7: EXPENSE | M7: MATERIAL | N7: LABOR | O7: EXPENSE | Y7: 46045
C8: ■ Direct construction cost
C9: =Details!C4 -> ■POD INSPECTION | F9: L/S | L9: =SUM(L10:L15) -> 470212.21 | M9: =SUM(M10:M14) -> 244974.04 | N9: =SUM(N10:N14) -> 185226.87 | O9: =SUM(O10:O14) -> 30711.3
C10: =" "&C58 -> □ POWER DISTRIBUTION PLAN | F10: L/S | G10: 1 | H10: =M10 -> 188331.94 | I10: =N10 -> 123434.87 | J10: =O10 -> 22472.55 | L10: =L92 -> 334239.36 | M10: =M92 -> 188331.94 | N10: =N92 -> 123434.87 | O10: =O92 -> 22472.55
C11: =" "&C93 -> □ GROUNDING PLAN | F11: L/S | G11: 1 | H11: =M11 -> 11212.46 | I11: =N11 -> 8627.79 | J11: =O11 -> 1414.64 | L11: =L101 -> 21254.89 | M11: =M101 -> 11212.46 | N11: =N101 -> 8627.79 | O11: =O101 -> 1414.64
C12: =" "&C102 -> □ MECHANICAL POWER PLAN | F12: L/S | G12: 1 | H12: =M12 -> 15049.99 | I12: =N12 -> 10457.59 | J12: =O12 -> 1831.4 | L12: =L118 -> 27338.98 | M12: =M118 -> 15049.99 | N12: =N118 -> 10457.59 | O12: =O118 -> 1831.4
B13: VPC Parking lot B3_Highmast installation | C13: =" "&C119 -> □ LIGHTING PLAN | F13: L/S | G13: 1 | H13: =M13 -> 26672.25 | I13: =N13 -> 34514.34 | J13: =O13 -> 4204.61 | L13: =L133 -> 65391.2 | M13: =M133 -> 26672.25 | N13: =N133 -> 34514.34 | O13: =O133 -> 4204.61
C14: =" "&C134 -> □ RECEPTACLE PLAN | F14: L/S | G14: 1 | H14: =M14 -> 3707.4 | I14: =N14 -> 8192.28 | J14: =O14 -> 788.1 | L14: =L142 -> 12687.78 | M14: =M142 -> 3707.4 | N14: =N142 -> 8192.28 | O14: =O142 -> 788.1
C15: □ RENTAL EQUIPMENT | F15: L/S | G15: 1 | H15: =M15 -> 0 | I15: =N15 -> 0 | J15: =O15 -> 9300 | L15: =L148 -> 9300 | M15: =M148 -> 0 | N15: =N148 -> 0 | O15: =O148 -> 9300
C16: Sub. Total | L16: =L9 -> 470212.21 | M16: =M9 -> 244974.04 | N16: =N9 -> 185226.87 | O16: =O9 -> 30711.3
B17: Parking lot C1_Highmast installation | C17: ■ Indirect construction cost
C18: SAFETY / MANAGEMENT | F18: L/S | G18: 1 | L18: =SUM(L10:L14)*0.0409 -> 18851.309
C20: Sub. Total | L20: =SUM(L18:L19) -> 18851.309 | M20: =SUM(M18:M19) -> 0 | N20: =SUM(N18:N19) -> 0 | O20: =SUM(O18:O19) -> 0
C21: Grand Total | L21: =L20+L16 -> 489063.52
P35: G. TOTAL
C56: =C9 -> ■POD INSPECTION
C57: =Details!C5&Details!D5 -> 1.POD INSPECTION
B58: =C58&E58 -> □ POWER DISTRIBUTION PLAN | C58: =Details!C6 -> □ POWER DISTRIBUTION PLAN
B59: =C59&E59 -> NEW PANEL(PO-8001)600 AMP 480/277V NEMA1 | C59: NEW PANEL(PO-8001) | E59: 600 AMP 480/277V NEMA1 | F59: EA | G59: 1 | H59: 12145 | I59: 680 | J59: =(H59*0.08)+(I59*0.06) -> 1012.4 | K59: =SUM(H59:J59) -> 13837.4 | L59: =SUM(M59:O59) -> 13837.4 | M59: =TRUNC(G59*H59,2) -> 12145 | N59: =TRUNC(G59*I59,2) -> 680 | O59: =TRUNC(G59*J59,2) -> 1012.4
B60: =C60&E60 -> TRANSFORMER (TRO-8001)45KVA 480:208/120V) | C60: TRANSFORMER (TRO-8001) | E60: 45KVA 480:208/120V) | F60: EA | G60: 1 | H60: 3887 | I60: 800 | J60: =(H60*0.08)+(I60*0.06) -> 358.96 | K60: =SUM(H60:J60) -> 5045.96 | L60: =SUM(M60:O60) -> 5045.96 | M60: =TRUNC(G60*H60,2) -> 3887 | N60: =TRUNC(G60*I60,2) -> 800 | O60: =TRUNC(G60*J60,2) -> 358.96
B61: =C61&E61 -> NEW PANEL(PO-LDP)125 AMP 208/120V 3PH,4W 42CKT | C61: NEW PANEL(PO-LDP) | E61: 125 AMP 208/120V 3PH,4W 42CKT | F61: EA | G61: 1 | H61: 1600 | I61: 340 | J61: =(H61*0.08)+(I61*0.06) -> 148.4 | K61: =SUM(H61:J61) -> 2088.4 | L61: =SUM(M61:O61) -> 2088.4 | M61: =TRUNC(G61*H61,2) -> 1600 | N61: =TRUNC(G61*I61,2) -> 340 | O61: =TRUNC(G61*J61,2) -> 148.4
B62: =C62&E62 -> PVC CONDUIT, SCHEDULE 404" | C62: PVC CONDUIT, SCHEDULE 40 | E62: 4" | F62: FT | G62: 2000 | H62: 8.1128823 | I62: 11 | J62: =(H62*0.08)+(I62*0.06) -> 1.3090306 | K62: =SUM(H62:J62) -> 20.421913 | L62: =SUM(M62:O62) -> 40843.82 | M62: =TRUNC(G62*H62,2) -> 16225.76 | N62: =TRUNC(G62*I62,2) -> 22000 | O62: =TRUNC(G62*J62,2) -> 2618.06
B63: =C63&E63 -> PVC CONDUIT, SCHEDULE 40 ELBOW4" | C63: PVC CONDUIT, SCHEDULE 40 ELBOW | E63: 4" | F63: FT | G63: 8 | H63: 21.76537 | I63: 15 | J63: =(H63*0.08)+(I63*0.06) -> 2.6412296 | K63: =SUM(H63:J63) -> 39.4066 | L63: =SUM(M63:O63) -> 315.24 | M63: =TRUNC(G63*H63,2) -> 174.12 | N63: =TRUNC(G63*I63,2) -> 120 | O63: =TRUNC(G63*J63,2) -> 21.12
B64: =C64&E64 -> MANHOLE (CONCRETE TYPE)5'W x 5'H x 5'D | C64: MANHOLE (CONCRETE TYPE) | E64: 5'W x 5'H x 5'D | F64: EA | G64: 5 | H64: 7200 | I64: 5800 | J64: =(H64*0.08)+(I64*0.06) -> 924 | K64: =SUM(H64:J64) -> 13924 | L64: =SUM(M64:O64) -> 69620 | M64: =TRUNC(G64*H64,2) -> 36000 | N64: =TRUNC(G64*I64,2) -> 29000 | O64: =TRUNC(G64*J64,2) -> 4620
B65: =C65&E65 -> Asphalt cutting, Excavate, Concrete back filling, Asphalt finish3'W x 4'H (Asphalt cutting) 110ft | C65: Asphalt cutting, Excavate, Concrete back filling, Asphalt finish | E65: 3'W x 4'H (Asphalt cutting) 110ft | F65: FT | G65: 1000 | H65: 16.4 | I65: 9.8 | J65: =(H65*0.08)+(I65*0.06) -> 1.9 | K65: =SUM(H65:J65) -> 28.1 | L65: =SUM(M65:O65) -> 28100 | M65: =TRUNC(G65*H65,2) -> 16400 | N65: =TRUNC(G65*I65,2) -> 9800 | O65: =TRUNC(G65*J65,2) -> 1900
B66: =C66&E66 -> Single Conductor (THHN/THWN) - StrandedAWG #350 | C66: Single Conductor (THHN/THWN) - Stranded | E66: AWG #350 | F66: EA | G66: 8800 | H66: 9.84 | I66: 5.72 | J66: =(H66*0.08)+(I66*0.06) -> 1.1304 | K66: =SUM(H66:J66) -> 16.6904 | L66: =SUM(M66:O66) -> 146875.52 | M66: =TRUNC(G66*H66,2) -> 86592 | N66: =TRUNC(G66*I66,2) -> 50336 | O66: =TRUNC(G66*J66,2) -> 9947.52
B67: =C67&E67 -> Single Conductor (THHN/THWN) - StrandedAWG #1/0 (GROUNDING) | C67: Single Conductor (THHN/THWN) - Stranded | E67: AWG #1/0 (GROUNDING) | F67: FT | G67: 2200 | H67: 3.344 | I67: 1.8 | J67: =(H67*0.08)+(I67*0.06) -> 0.37552 | K67: =SUM(H67:J67) -> 5.51952 | L67: =SUM(M67:O67) -> 12142.94 | M67: =TRUNC(G67*H67,2) -> 7356.8 | N67: =TRUNC(G67*I67,2) -> 3960 | O67: =TRUNC(G67*J67,2) -> 826.14
B68: =C68&E68 -> LIQUIDTIGHT FLEXIBLE CONDUIT1-1/2" | C68: LIQUIDTIGHT FLEXIBLE CONDUIT | E68: 1-1/2" | F68: EA | G68: 6 | H68: 6.1776807 | I68: 8.53875 | J68: =(H68*0.08)+(I68*0.06) -> 1.0065395 | K68: =SUM(H68:J68) -> 15.72297 | L68: =SUM(M68:O68) -> 94.32 | M68: =TRUNC(G68*H68,2) -> 37.06 | N68: =TRUNC(G68*I68,2) -> 51.23 | O68: =TRUNC(G68*J68,2) -> 6.03 | RV68: 18.84 | RW68: =12.09*1.2 -> 14.508
B69: =C69&E69 -> CONDUIT HANGER SUPPORT1-1/2" | C69: CONDUIT HANGER SUPPORT | E69: 1-1/2" | F69: FT | G69: 4 | H69: 12.38 | I69: 14.66 | J69: =(H69*0.08)+(I69*0.06) -> 1.87 | K69: =SUM(H69:J69) -> 28.91 | L69: =SUM(M69:O69) -> 115.64 | M69: =TRUNC(G69*H69,2) -> 49.52 | N69: =TRUNC(G69*I69,2) -> 58.64 | O69: =TRUNC(G69*J69,2) -> 7.48
B70: =C70&E70 -> ELECTRICAL METALLIC TUBING (EMT)+FITTING1-1/2" | C70: ELECTRICAL METALLIC TUBING (EMT)+FITTING | E70: 1-1/2" | F70: EA | G70: 10 | H70: 3.1022035 | I70: 4.269375 | J70: =(H70*0.08)+(I70*0.06) -> 0.50433878 | K70: =SUM(H70:J70) -> 7.8759173 | L70: =SUM(M70:O70) -> 78.75 | M70: =TRUNC(G70*H70,2) -> 31.02 | N70: =TRUNC(G70*I70,2) -> 42.69 | O70: =TRUNC(G70*J70,2) -> 5.04
B71: =C71&E71 -> Single Conductor (THHN/THWN-2) - StrandedAWG#4 | C71: Single Conductor (THHN/THWN-2) - Stranded | E71: AWG#4 | F71: FT | G71: 60 | H71: 2.0288946 | I71: 1.449 | J71: =(H71*0.08)+(I71*0.06) -> 0.24925157 | K71: =SUM(H71:J71) -> 3.7271462 | L71: =SUM(M71:O71) -> 223.62 | M71: =TRUNC(G71*H71,2) -> 121.73 | N71: =TRUNC(G71*I71,2) -> 86.94 | O71: =TRUNC(G71*J71,2) -> 14.95
B72: =C72&E72 -> Single Conductor (THHN/THWN-2) - StrandedAWG#8(GROUNDING) | C72: Single Conductor (THHN/THWN-2) - Stranded | E72: AWG#8(GROUNDING) | F72: EA | G72: 20 | H72: 0.58891543 | I72: 0.905625 | J72: =(H72*0.08)+(I72*0.06) -> 0.10145073 | K72: =SUM(H72:J72) -> 1.5959912 | L72: =SUM(M72:O72) -> 31.9 | M72: =TRUNC(G72*H72,2) -> 11.77 | N72: =TRUNC(G72*I72,2) -> 18.11 | O72: =TRUNC(G72*J72,2) -> 2.02
B73: =C73&E73 -> Single Conductor (THHN/THWN-2) - StrandedAWG#1 | C73: Single Conductor (THHN/THWN-2) - Stranded | E73: AWG#1 | F73: FT | G73: 80 | H73: 2.33 | I73: 1.64 | J73: =(H73*0.08)+(I73*0.06) -> 0.2848 | K73: =SUM(H73:J73) -> 4.2548 | L73: =SUM(M73:O73) -> 340.38 | M73: =TRUNC(G73*H73,2) -> 186.4 | N73: =TRUNC(G73*I73,2) -> 131.2 | O73: =TRUNC(G73*J73,2) -> 22.78
B74: =C74&E74 -> Single Conductor (THHN/THWN-2) - StrandedAWG#6(GROUNDING) | C74: Single Conductor (THHN/THWN-2) - Stranded | E74: AWG#6(GROUNDING) | F74: EA | G74: 20 | H74: 0.87 | I74: 1.04 | J74: =(H74*0.08)+(I74*0.06) -> 0.132 | K74: =SUM(H74:J74) -> 2.042 | L74: =SUM(M74:O74) -> 40.84 | M74: =TRUNC(G74*H74,2) -> 17.4 | N74: =TRUNC(G74*I74,2) -> 20.8 | O74: =TRUNC(G74*J74,2) -> 2.64
...

Sheet Details
C1: Project:POD INSPECTION
C2: No. | D2: Description | E2: Specification | F2: Units | G2: Calculation | I2: Quantity
G3: dist. | H3: piece
A4: 1 | C4: ■POD INSPECTION
A5: =A4+1 -> 2 | B5: =D5&E5 | C5: 1.POD INSPECTION
A6: =A5+1 -> 3 | B6: =D6&E6 -> NEW PANEL(PO-8001)600 AMP 480/277V NEMA1 | C6: □ POWER DISTRIBUTION PLAN | D6: NEW PANEL(PO-8001) | E6: 600 AMP 480/277V NEMA1 | F6: EA | G6: 1 | H6: 1 | I6: =G6*H6 -> 1
A7: =#REF!+1 -> #REF! | B7: =D7&E7 -> TRANSFORMER (TRO-8001)45KVA 480:208/120V NEMA1 | D7: TRANSFORMER (TRO-8001) | E7: 45KVA 480:208/120V NEMA1 | F7: EA | G7: 1 | H7: 1 | I7: =G7*H7 -> 1
A8: =#REF!+1 -> #REF! | B8: =D8&E8 -> NEW PANEL(PO-LDP)125 AMP 208/120V 3PH,4W 42CKT | D8: NEW PANEL(PO-LDP) | E8: 125 AMP 208/120V 3PH,4W 42CKT | F8: FT | G8: 1 | H8: 1 | I8: =G8*H8 -> 1
A9: =#REF!+1 -> #REF! | B9: =D9&E9 -> PVC CONDUIT, SCHEDULE 404" | D9: PVC CONDUIT, SCHEDULE 40 | E9: 4" | F9: FT | G9: 1000 | H9: 2 | I9: =G9*H9 -> 2000
A10: =#REF!+1 -> #REF! | B10: =D10&E10 -> PVC CONDUIT, SCHEDULE 40 ELBOW4" | D10: PVC CONDUIT, SCHEDULE 40 ELBOW | E10: 4" | F10: EA | G10: 8 | H10: 1 | I10: =G10*H10 -> 8
A11: =#REF!+1 -> #REF! | B11: =D11&E11 -> MANHOLE (CONCRETE TYPE)5'W x 5'H x 5'D | D11: MANHOLE (CONCRETE TYPE) | E11: 5'W x 5'H x 5'D | F11: EA | G11: 5 | H11: 1 | I11: =G11*H11 -> 5
A12: =#REF!+1 -> #REF! | B12: =D12&E12 -> Asphalt cutting, Excavate, Concrete back filling, Asphalt finish3'W x 4'H (Asphalt cutting) 110ft | D12: Asphalt cutting, Excavate, Concrete back filling, Asphalt finish | E12: 3'W x 4'H (Asphalt cutting) 110ft | F12: FT | G12: 1000 | H12: 1 | I12: =G12*H12 -> 1000
A13: =A5+1 -> 3 | B13: =D13&E13 -> Single Conductor (THHN/THWN) - StrandedAWG #350 | D13: Single Conductor (THHN/THWN) - Stranded | E13: AWG #350 | F13: FT | G13: 1100 | H13: 8 | I13: =G13*H13 -> 8800
A14: =A6+1 -> 4 | B14: =D14&E14 -> Single Conductor (THHN/THWN) - StrandedAWG #1/0 (GROUNDING) | D14: Single Conductor (THHN/THWN) - Stranded | E14: AWG #1/0 (GROUNDING) | F14: FT | G14: 1100 | H14: 2 | I14: =G14*H14 -> 2200
A15: =#REF!+1 -> #REF! | B15: =D15&E15 -> LIQUIDTIGHT FLEXIBLE CONDUIT1-1/2" | D15: LIQUIDTIGHT FLEXIBLE CONDUIT | E15: 1-1/2" | F15: FT | G15: 6 | H15: 1 | I15: =G15*H15 -> 6
A16: =#REF!+1 -> #REF! | B16: =D16&E16 -> CONDUIT HANGER SUPPORT1-1/2" | D16: CONDUIT HANGER SUPPORT | E16: 1-1/2" | F16: SET | G16: 4 | H16: 1 | I16: =G16*H16 -> 4
A17: =A9+1 -> #REF! | B17: =D17&E17 -> ELECTRICAL METALLIC TUBING (EMT)+FITTING1-1/2" | D17: ELECTRICAL METALLIC TUBING (EMT)+FITTING | E17: 1-1/2" | F17: FT | G17: 10 | H17: 1 | I17: =G17*H17 -> 10
A18: =A17+1 -> #REF! | B18: LG ENERGY SOLUTION | D18: Single Conductor (THHN/THWN-2) - Stranded | E18: AWG#4 | F18: FT | G18: 20 | H18: 3 | I18: =G18*H18 -> 60
A19: =A18+1 -> #REF! | B19: Parking lot C1_Highmast installation | D19: Single Conductor (THHN/THWN-2) - Stranded | E19: AWG#8(GROUNDING) | F19: FT | G19: 20 | H19: 1 | I19: =G19*H19 -> 20
A20: =A19+1 -> #REF! | B20: =D20&E20 -> Single Conductor (THHN/THWN-2) - StrandedAWG#1 | D20: Single Conductor (THHN/THWN-2) - Stranded | E20: AWG#1 | F20: FT | G20: 20 | H20: 4 | I20: =G20*H20 -> 80
B21: =D21&E21 -> Single Conductor (THHN/THWN-2) - StrandedAWG#6(GROUNDING) | D21: Single Conductor (THHN/THWN-2) - Stranded | E21: AWG#6(GROUNDING) | F21: FT | G21: 20 | H21: 1 | I21: =G21*H21 -> 20
B22: =D22&E22 -> LIQUIDTIGHT FLEXIBLE CONDUIT2" | D22: LIQUIDTIGHT FLEXIBLE CONDUIT | E22: 2" | F22: FT | G22: 6 | H22: 1 | I22: =G22*H22 -> 6
B23: =D23&E23 -> ELECTRICAL METALLIC TUBING (EMT)+FITTING2" | D23: ELECTRICAL METALLIC TUBING (EMT)+FITTING | E23: 2" | F23: FT | G23: 10 | H23: 1 | I23: =G23*H23 -> 10
B24: =D24&E24 -> CONDUIT HANGER SUPPORT2" | D24: CONDUIT HANGER SUPPORT | E24: 2" | F24: SET | G24: 4 | H24: 1 | I24: =G24*H24 -> 4
B25: =D25&E25 -> PVC CONDUIT, SCHEDULE 401" ( TR Ground) | D25: PVC CONDUIT, SCHEDULE 40 | E25: 1" ( TR Ground) | F25: FT | G25: 30 | H25: 1 | I25: =G25*H25 -> 30
B26: =D26&E26 -> Single Conductor (THHN/THWN-2) - StrandedAWG#6(TR GROUNDING) | D26: Single Conductor (THHN/THWN-2) - Stranded | E26: AWG#6(TR GROUNDING) | F26: FT | G26: 30 | H26: 1 | I26: =G26*H26 -> 30
B27: =D27&E27 -> CONNECTION AND TERMINATION#350 Kcmil COMPRESSION TYPE | D27: CONNECTION AND TERMINATION | E27: #350 Kcmil COMPRESSION TYPE | F27: EA | G27: 8 | H27: 2 | I27: =G27*H27 -> 16
B28: =D28&E28 -> CONNECTION AND TERMINATIONAWG#1/0 COMPRESSION TYPE | D28: CONNECTION AND TERMINATION | E28: AWG#1/0 COMPRESSION TYPE | F28: EA | G28: 2 | H28: 2 | I28: =G28*H28 -> 4
B29: =D29&E29 -> CONNECTION AND TERMINATIONAWG#1 COMPRESSION TYPE | D29: CONNECTION AND TERMINATION | E29: AWG#1 COMPRESSION TYPE | F29: EA | G29: 4 | H29: 2 | I29: =G29*H29 -> 8
B30: =D30&E30 -> CONNECTION AND TERMINATIONAWG#4 COMPRESSION TYPE | D30: CONNECTION AND TERMINATION | E30: AWG#4 COMPRESSION TYPE | F30: EA | G30: 3 | H30: 2 | I30: =G30*H30 -> 6
B31: =D31&E31 -> CONNECTION AND TERMINATIONAWG#6 COMPRESSION TYPE | D31: CONNECTION AND TERMINATION | E31: AWG#6 COMPRESSION TYPE | F31: EA | G31: 2 | H31: 1 | I31: =G31*H31 -> 2
B32: =D32&E32 -> CONNECTION AND TERMINATIONAWG#8 COMPRESSION TYPE | D32: CONNECTION AND TERMINATION | E32: AWG#8 COMPRESSION TYPE | F32: EA | G32: 4 | H32: 1 | I32: =G32*H32 -> 4
B33: =D33&E33 -> ALUMINUM CABLE TRAY (LADDER TYPE)24"Width, 4"height, 9"rung spacing | D33: ALUMINUM CABLE TRAY (LADDER TYPE) | E33: 24"Width, 4"height, 9"rung spacing | F33: FT | G33: =(150+20) -> 170 | H33: 1 | I33: =G33*H33 -> 170
B34: =D34&E34 -> ALUMINUM HORIZONTAL ELBOW (LADDER TYPE)24"Width, 4"height, 9"rung spacing | D34: ALUMINUM HORIZONTAL ELBOW (LADDER TYPE) | E34: 24"Width, 4"height, 9"rung spacing | F34: EA | G34: 2 | H34: 1 | I34: =G34*H34 -> 2
B35: =D35&E35 -> ALUMINUM VERTICAL ELBOW (LADDER TYPE)24"Width, 4"height, 9"rung spacing | D35: ALUMINUM VERTICAL ELBOW (LADDER TYPE) | E35: 24"Width, 4"height, 9"rung spacing | F35: EA | G35: 1 | H35: 1 | I35: =G35*H35 -> 1 | P35: G. TOTAL
B36: =D36&E36 -> CABLE TRAY SUPPORT24" Width including beam clamp, square washer, unistrut, 2 rods(length:4ft~8ft, dia: 9/16"), etc | D36: CABLE TRAY SUPPORT | E36: 24" Width including beam clamp, square washer, unistrut, 2 rods(length:4ft~8ft, dia: 9/16"), etc | F36: SET | G36: 29 | H36: 1 | I36: =G36*H36 -> 29
B37: =D37&E37 -> CABLE TRAY BONDING JUMPER12" | D37: CABLE TRAY BONDING JUMPER | E37: 12" | F37: EA | G37: 22 | H37: 1 | I37: =G37*H37 -> 22
B38: =D38&E38 | I38: =G38*H38 -> 0
B39: =D39&E39 | C39: □ GROUNDING PLAN | I39: =G39*H39 -> 0
B40: =D40&E40 -> Single Conductor (THHN/THWN) - BAREAWG#4/0(GROUNDING) | D40: Single Conductor (THHN/THWN) - BARE | E40: AWG#4/0(GROUNDING) | F40: FT | G40: =(460+80) -> 540 | H40: 1 | I40: =G40*H40 -> 540
...
